<robot name="lc_soft_enable_wide_grip">
	<link name="base_link">
		<collision>
			<geometry>
				<mesh filename="asset/lc_soft_enable_wide_grip/meshes/lc_soft_enable_wide_grip_Base_SWA_collision.stl" scale="1.0 1.0 1.0" />
			</geometry>
			<origin rpy="0 0 0" xyz="0 0 0" />
		</collision>
		<visual>
			<geometry>
				<mesh filename="asset/lc_soft_enable_wide_grip/meshes/lc_soft_enable_wide_grip_Base_SWA.stl" scale="1.0 1.0 1.0" />
			</geometry>
			<origin rpy="0 0 0" xyz="0 0 0" />
			<material name="lc_soft_enable_wide_grip_Base_SWA.stl">
				<color rgba="0.4891 0.5125 0.5281 1.0" />
			</material>
		</visual>
		<inertial>
			<inertia ixx="0.0020471396" ixy="1.0230695e-06" ixz="1.5904729e-06" iyy="0.0018800969" iyz="2.8524699e-05" izz="0.00095747688" />
			<origin rpy="0 0 0" xyz="-3.6448476e-05 0.0038471551 0.068296546" />
			<mass value="0.98136109" />
		</inertial>
	</link>
	<link name="right_finger_link">
		<collision>
			<geometry>
				<mesh filename="asset/lc_soft_enable_wide_grip/meshes/lc_soft_enable_wide_grip_Right_Base_RIGHT_BASE_collision.stl" scale="1.0 1.0 1.0" />
			</geometry>
			<origin rpy="0 0 0" xyz="0 0 0" />
		</collision>
		<visual>
			<geometry>
				<mesh filename="asset/lc_soft_enable_wide_grip/meshes/lc_soft_enable_wide_grip_Right_Base_RIGHT_BASE.stl" scale="1.0 1.0 1.0" />
			</geometry>
			<origin rpy="0 0 0" xyz="0 0 0" />
			<material name="lc_soft_enable_wide_grip_Right_Base_RIGHT_BASE.stl">
				<color rgba="0.4891 0.5125 0.5281 1.0" />
			</material>
		</visual>
		<inertial>
			<inertia ixx="4.9817353e-05" ixy="-1.7815308e-06" ixz="9.6357237e-06" iyy="0.00011555571" iyz="1.4126845e-07" izz="0.00014948194" />
			<origin rpy="0 0 0" xyz="0.02906453 0.00030634989 -0.0055044388" />
			<mass value="0.19324581" />
		</inertial>
	</link>
	<link name="right_tip_link">
		<collision>
			<geometry>
				<mesh filename="asset/lc_soft_enable_wide_grip/meshes/right_distal_50_6.stl" scale="0.001 0.001 0.001" />
			</geometry>
			<origin rpy="0 0 0" xyz="0 0 0" />
		</collision>
		<visual>
			<geometry>
				<mesh filename="asset/lc_soft_enable_wide_grip/meshes/right_distal_50_6.stl" scale="0.001 0.001 0.001" />
			</geometry>
			<origin rpy="0 0 0" xyz="0 0 0" />
			<material name="lc_soft_enable_wide_grip_Right_Distal_RIGHT_DISTAL.stl">
				<color rgba="0.4891 0.5125 0.5281 1.0" />
			</material>
		</visual>
		<inertial>
			<inertia ixx="1.7886388e-06" ixy="1.592602e-07" ixz="1.4823976e-08" iyy="2.7154831e-06" iyz="-2.2444927e-09" izz="1.1190624e-06" />
			<origin rpy="0 0 0" xyz="0.013070583 -0.0022292525 9.2964541e-05" />
			<mass value="0.01222309" />
		</inertial>
	</link>
	<link name="left_finger">
		<collision>
			<geometry>
				<mesh filename="asset/lc_soft_enable_wide_grip/meshes/lc_soft_enable_wide_grip_Left_Base_left_base_collision.stl" scale="1.0 1.0 1.0" />
			</geometry>
			<origin rpy="0 0 0" xyz="0 0 0" />
		</collision>
		<visual>
			<geometry>
				<mesh filename="asset/lc_soft_enable_wide_grip/meshes/lc_soft_enable_wide_grip_Left_Base_left_base.stl" scale="1.0 1.0 1.0" />
			</geometry>
			<origin rpy="0 0 0" xyz="0 0 0" />
			<material name="lc_soft_enable_wide_grip_Left_Base_left_base.stl">
				<color rgba="0.4891 0.5125 0.5281 1.0" />
			</material>
		</visual>
		<inertial>
			<inertia ixx="4.9817353e-05" ixy="-1.7815308e-06" ixz="9.6357237e-06" iyy="0.00011555571" iyz="1.4126845e-07" izz="0.00014948194" />
			<origin rpy="0 0 0" xyz="0.02906453 0.00030634989 -0.0055044388" />
			<mass value="0.19324581" />
		</inertial>
	</link>
	<link name="left_tip_link">
		<collision>
			<geometry>
				<mesh filename="asset/lc_soft_enable_wide_grip/meshes/left_distal_50_6.stl" scale="0.001 0.001 0.001" />
			</geometry>
			<origin rpy="0 0 0" xyz="0 0 0" />
		</collision>
		<visual>
			<geometry>
				<mesh filename="asset/lc_soft_enable_wide_grip/meshes/left_distal_50_6.stl" scale="0.001 0.001 0.001" />
			</geometry>
			<origin rpy="0 0 0" xyz="0 0 0" />
			<material name="lc_soft_enable_wide_grip_Left_Distal_LEFT_DISTAL.stl">
				<color rgba="0.4891 0.5125 0.5281 1.0" />
			</material>
		</visual>
		<inertial>
			<inertia ixx="1.7886388e-06" ixy="1.592602e-07" ixz="1.4823976e-08" iyy="2.7154831e-06" iyz="-2.2444927e-09" izz="1.1190624e-06" />
			<origin rpy="0 0 0" xyz="0.013070583 -0.0022292525 9.2964541e-05" />
			<mass value="0.01222309" />
		</inertial>
	</link>
	<joint name="right_finger" type="prismatic">
		<parent link="base_link" />
		<child link="right_finger_link" />
		<axis xyz="0 0 1" />
		<limit effort="100000000000000000" lower="0" upper="0.0575" velocity="100000000000000000" />
		<origin rpy="-3.141592653589793 -1.5707963057214722 0" xyz="-0.07658 -4.689172593935216e-18 0.1335" />
	</joint>
	<joint name="right_tip" type="revolute">
		<parent link="right_finger_link" />
		<child link="right_tip_link" />
		<axis xyz="0 0 1" />
		<limit effort="100000000000000000" lower="-0.17" upper="1.74" velocity="100000000000000000" />
		<origin rpy="1.5707963267948966 2.220446049250313e-16 -1.2246467991473535e-16" xyz="0.0715 -4.727136644708785e-19 -0.00772" />
	</joint>
	<joint name="left_base" type="prismatic">
		<parent link="base_link" />
		<child link="left_finger" />
		<axis xyz="0 0 1" />
		<limit effort="100000000000000000" lower="0" upper="0.0575" velocity="100000000000000000" />
		<origin rpy="1.874699728327322e-33 -1.5707963057214722 0" xyz="0.07658 4.689172593935216e-18 0.1335" />
	</joint>
	<joint name="left_tip" type="revolute">
		<parent link="left_finger" />
		<child link="left_tip_link" />
		<axis xyz="0 0 1" />
		<limit effort="100000000000000000" lower="0" upper="1.74" velocity="100000000000000000" />
		<origin rpy="1.5707963267948966 2.220446049250313e-16 -1.2246467991473532e-16" xyz="0.0715 4.727136644708785e-19 -0.00772" />
	</joint>
</robot>